#include <iostream>
#include <cstdlib>
#include <exception>

void return_and_stop(int n) {
    if (n == 0) {
        return;
    }
    std::exit(EXIT_FAILURE);
}

// A simple assertion function for demonstration
void assertTest(bool condition, const std::string& testName) {
    if (!condition) {
        std::cout << "Test failed: " << testName << std::endl;
        std::exit(EXIT_FAILURE); // Exit the program with a failure status
    } else {
        std::cout << "Test passed: " << testName << std::endl;
    }
}

int main() {
    // Since we cannot normally test std::exit without terminating our program,
    // we can't directly test `return_and_stop(1)` without ending our test suite prematurely.
    // Instead, we focus on the test case we can check.
    
    // Test 1: n == 0 should simply return and not stop the program.
    try {
        return_and_stop(0); // This should not terminate the program
        assertTest(true, "return_and_stop(0) returns without stopping");
    } catch (...) {
        // If an unexpected exception is thrown, the test fails.
        assertTest(false, "return_and_stop(0) threw an unexpected exception");
    }

    // Note on testing `return_and_stop(1)`:
    // Testing behavior that involves calling `std::exit` is complex in a unit test
    // because it halts execution. Normally, you'd use mock objects, dependency injection,
    // or similar techniques to isolate and test such behavior, which might be beyond
    // the scope of a simple test setup like this.

    return 0; // Return successful exit status
}